<?xml version="1.0"?>
<robot xmlns:xacro="http://www.ros.org/wiki/xacro"  name="robot_5a_urdf">

    <xacro:include filename="physics_include.xacro" />
    <xacro:include filename="simulation_gazebo.xacro" />

    <link name="world"></link>

    <joint name="base_joint" type="fixed">
      <origine xyz="1.5 1.0 0" rpy="0 0 0"/>
      <parent link="world"/>
      <child link="base_link"/> 
    </joint>

    <link name="base_link">
      <inertial>
        <origin xyz="-0.0548860380843249 0.13093941386242 0.123490600745143" rpy="0 0 0"/>
        <mass value="8.0643" />
      <inertia ixx="0.11291" ixy="0.00066071" ixz="-0.00030472" iyy="0.089946" iyz="0.011461" izz="0.19187"/>
      </inertial>
      <visual>
        <origin xyz="0 0 0" rpy="0 0 0"/>
        <geometry>
          <mesh filename="file://$(find robot_5a_urdf)/meshes/base_link.STL"/>
        </geometry>
        <material name="green" />
      </visual>
      <collision>
        <origin xyz="0 0 0" rpy="0 0 0"/>
        <geometry>
          <mesh filename="file://$(find robot_5a_urdf)/meshes/base_link.STL"/>
        </geometry>
      </collision>
    </link>

    <link name="Link_1">
      <inertial>
        <origin xyz="-0.021301 0.065037 0.0075714" rpy="0 0 0"/>
        <mass value="4.2526" />
        <inertia ixx="0.0034071" ixy="8.9041E-06" ixz="1.179E-07"
                   iyy="0.018642" iyz="-3.6544E-06" izz="0.021987" />
      </inertial>
      <visual>
        <origin xyz="0 0 0" rpy="0 0 0"/>
        <geometry>
          <mesh filename="file://$(find robot_5a_urdf)/meshes/Link_1.STL"/>
        </geometry>
        <material name="blue" />
      </visual>
      <collision>
        <origin xyz="0 0 0" rpy="0 0 0"/>
        <geometry>
          <mesh filename="file://$(find robot_5a_urdf)/meshes/Link_1.STL"/>
        </geometry>
      </collision>
    </link>

    <joint name="Joint_1" type="revolute">
      <origin xyz="-0.035213 -0.13463 0.065903" rpy="1.5708 0 -0.85661"/>
      <parent link="base_link"/>
      <child link="Link_1"/>
      <axis xyz="0 1 0"/>
      <limit lower="-1.5707" upper="1.5707" effort="100" velocity="100"/>
      <dynamics damping="2.0" friction="2.0"/>
    </joint>

    <link name="Link_2">
      <inertial>
        <origin xyz="0.0103079949986939 -0.10122359821804 0.0158561314021889" rpy="0 0 0"/>
        <mass value="1.9323" />
        <inertia ixx="0.012138" ixy="-3.5576E-06" ixz="-9.0632E-06"
                   iyy="0.011445" iyz="0.00014273" izz="0.00070271" />
      </inertial>
      <visual>
        <origin xyz="0 0 0" rpy="0 0 0"/>
        <geometry>
          <mesh filename="file://$(find robot_5a_urdf)/meshes/Link_2.STL"/>
        </geometry>
        <material name="orange" />
      </visual>
      <collision>
        <origin xyz="0 0 0" rpy="0 0 0"/>
        <geometry>
          <mesh filename="file://$(find robot_5a_urdf)/meshes/Link_2.STL"/>
        </geometry>
      </collision>
    </link>

    <joint name="Joint_2" type="revolute">
      <origin xyz="0 0.1655 0" rpy="-2.7886 0.7558 3.1416"/>
      <parent link="Link_1"/>
      <child link="Link_2"/>
      <axis xyz="1 0 0"/>
      <limit lower="-1.5707" upper="1.5707" effort="100" velocity="100"/>
      <dynamics damping="2.0" friction="2.0"/>
    </joint>

    <link name="Link_3">
      <inertial>
        <origin xyz="0.20022943071033 -0.0103079949986938 0.253115452864687" rpy="0 0 0"/>
        <mass value="1.1381" />
        <inertia ixx="0.00023572" ixy="-3.8425E-06" ixz="4.1286E-06"
                   iyy="0.00029123" iyz="-1.0387E-07" izz="0.00052457" />
      </inertial>
      <visual>
        <origin xyz="0 0 0" rpy="0 0 0"/>
        <geometry>
          <mesh filename="file://$(find robot_5a_urdf)/meshes/Link_3.STL"/>
        </geometry>
        <material name="white" />
      </visual>
      <collision>
        <origin xyz="0 0 0" rpy="0 0 0"/>
        <geometry>
          <mesh filename="file://$(find robot_5a_urdf)/meshes/Link_3.STL"/>
        </geometry>
      </collision>
    </link>

    <joint name="Joint_3" type="revolute">
      <origin xyz="0 0.22112 0" rpy="-3.1416 -0.95068 -1.5708"/>
      <parent link="Link_2"/>
      <child link="Link_3"/>
      <axis xyz="0 1 0"/>
      <limit lower="-1.5707" upper="1.5707" effort="100" velocity="100"/>
      <dynamics damping="2.0" friction="2.0"/>
    </joint>

    <link name="Link_4">
      <inertial>
        <origin xyz="0.229768913416455 -0.369352839223879 0.106888566945361" rpy="0 0 0"/>
        <mass value="0.62964" />
        <inertia ixx="0.0001717" ixy="1.3446E-06" ixz="8.5164E-06"
                   iyy="0.00010506" iyz="5.1412E-05" izz="7.8944E-05" />
      </inertial>
      <visual>
        <origin xyz="0 0 0" rpy="0 0 0"/>
        <geometry>
          <mesh filename="file://$(find robot_5a_urdf)/meshes/Link_4.STL"/>
        </geometry>
        <material name="blue" />
      </visual>
      <collision>
        <origin xyz="0 0 0" rpy="0 0 0"/>
        <geometry>
          <mesh filename="file://$(find robot_5a_urdf)/meshes/Link_4.STL"/>
        </geometry>
      </collision>
    </link>

    <joint name="Joint_4" type="revolute">
      <origin xyz="-0.16912 0.002 0" rpy="0 -1.184 1.5708"/>
      <parent link="Link_3"/>
      <child link="Link_4"/>
      <axis xyz="0 1 0"/>
      <limit lower="-1.5707" upper="1.5707" effort="100" velocity="100"/>
      <dynamics damping="2.0" friction="2.0"/>
    </joint>

    <link name="Link_5">
      <inertial>
        <origin xyz="0.3705564409974 0.106888566945361 0.30222256926485" rpy="0 0 0"/>
        <mass value="0.19875" />
        <inertia ixx="6.2676E-05" ixy="4.2551E-06" ixz="4.0215E-05"
                   iyy="9.7792E-05" iyz="8.5888E-07" izz="9.5807E-05" />
      </inertial>
      <visual>
        <origin xyz="0 0 0" rpy="0 0 0"/>
        <geometry>
          <mesh filename="file://$(find robot_5a_urdf)/meshes/Link_5.STL"/>
        </geometry>
        <material name="orange" />
      </visual>
      <collision>
        <origin xyz="0 0 0" rpy="0 0 0"/>
        <geometry>
          <mesh filename="file://$(find robot_5a_urdf)/meshes/Link_5.STL"/>
        </geometry>
      </collision>
    </link>

    <joint name="Joint_5" type="revolute">
      <origin xyz="0 0.05 0" rpy="1.5708 0 -0.38538"/>
      <parent link="Link_4"/>
      <child link="Link_5"/>
      <axis xyz="0 1 0"/>
      <limit lower="-1.5707" upper="1.5707" effort="100" velocity="100"/>
      <dynamics damping="2.0" friction="2.0"/>
    </joint>

    <xacro:include filename="example_gazebo.xacro" />

</robot>

<!-- test -->